```markdown
### Error Log

- **Installed Packages**: 3 packages installed in 42 ms.
- **Error Traceback**:
    - **File**: `/tmp/datagenmrt9km.py`, **Line**: 220, **Function**: `a8_credit_card_image`
        - Issue: `large_font = ImageFont.truetype("arial.ttf", size=60)`
    - **Subsequent Files**:
        - `/root/.cache/uv/environments-v2/fad51b5c0487eb6/lib/python3.13/site-packages/PIL/ImageFont.py`, **Line**: 879 (in `truetype`)
        - `/root/.cache/uv/environments-v2/fad51b5c0487eb6/lib/python3.13/site-packages/PIL/ImageFont.py`, **Line**: 876 (in `freetype`)
        - `/root/.cache/uv/environments-v2/fad51b5c0487eb6/lib/python3.13/site-packages/PIL/ImageFont.py`, **Line**: 284 (in `__init__`)

- **Specific Error**: `OSError: cannot open resource`

- **Further Exception Handling**:
    - **File**: `/tmp/datagenmrt9km.py`, **Line**: 303 (in `<module>`)
        - **Issue**: Repeated error in initiating `a8_credit_card_image`

- **File Details**:
    - **File**: `/tmp/datagenmrt9km.py`, **Line**: 224
        - `large_font = ImageFont.truetype("/usr/share/fonts/truetype/dejavusans/DejaVuSans.ttf", size=60)`

- **Final Error**: `OSError: cannot open resource` 

- **INFO Log**: 
    - `172.17.0.1:35176 - "POST /run?task=0&Install%60...&run+the+script+..."` (truncated for brevity)
```