{"id": 612775, "name": "Shivaditya Bhattacharya", "username": "22f3000819", "avatar_template": "/user_avatar/discourse.onlinedegree.iitm.ac.in/22f3000819/{size}/66738_2.png", "created_at": "2025-03-29T13:24:44.800Z", "cooked": "<p><a class=\"mention\" href=\"/u/carlton\">@carlton</a><br>\nMy docker logs shows that <code>OSError: Cannot find resource</code> error occurred when the data generation script tried to access font files in generation for a8.<br>\n<div class=\"lightbox-wrapper\"><a class=\"lightbox\" href=\"https://europe1.discourse-cdn.com/flex013/uploads/iitm/original/3X/d/f/dfc4c289dcc2ddda315bd9f97a9ff21c166792af.png\" data-download-href=\"/uploads/short-url/vVy1Zl2FILIE7YmcgLMAd1engpp.png?dl=1\" title=\"image\" rel=\"noopener nofollow ugc\"><img src=\"https://europe1.discourse-cdn.com/flex013/uploads/iitm/original/3X/d/f/dfc4c289dcc2ddda315bd9f97a9ff21c166792af.png\" alt=\"image\" data-base62-sha1=\"vVy1Zl2FILIE7YmcgLMAd1engpp\" width=\"690\" height=\"374\" data-dominant-color=\"F7F7F7\"><div class=\"meta\"><svg class=\"fa d-icon d-icon-far-image svg-icon\" aria-hidden=\"true\"><use href=\"#far-image\"></use></svg><span class=\"filename\">image</span><span class=\"informations\">1485\u00d7807 37.4 KB</span><svg class=\"fa d-icon d-icon-discourse-expand svg-icon\" aria-hidden=\"true\"><use href=\"#discourse-expand\"></use></svg></div></a></div></p>\n<p>The datagen.py script looked for Arial font in the try block and when it encountered error it went to the except block to use DejaVuSans, the Pillow default, except it encountered the same error there, which was not handled. Thus, datagen.py stopped abruptly without creating files for A9 and A10 as well. So effectively, my A9 and A10 did not get evaluated properly as it did not have the required files due to error during data generation for A8. Can you please re-evaluate by enclosing each of the data generation function calls in their own try-except blocks?<br>\n<div class=\"lightbox-wrapper\"><a class=\"lightbox\" href=\"https://europe1.discourse-cdn.com/flex013/uploads/iitm/original/3X/6/8/681a3a02c951eaf7014d116d45b9ac35b8fdd2de.png\" data-download-href=\"/uploads/short-url/eQVQww2TLZd4V84EezSUFxCArFA.png?dl=1\" title=\"image\" rel=\"noopener nofollow ugc\"><img src=\"https://europe1.discourse-cdn.com/flex013/uploads/iitm/original/3X/6/8/681a3a02c951eaf7014d116d45b9ac35b8fdd2de.png\" alt=\"image\" data-base62-sha1=\"eQVQww2TLZd4V84EezSUFxCArFA\" width=\"302\" height=\"252\"><div class=\"meta\"><svg class=\"fa d-icon d-icon-far-image svg-icon\" aria-hidden=\"true\"><use href=\"#far-image\"></use></svg><span class=\"filename\">image</span><span class=\"informations\">302\u00d7252 3.45 KB</span><svg class=\"fa d-icon d-icon-discourse-expand svg-icon\" aria-hidden=\"true\"><use href=\"#discourse-expand\"></use></svg></div></a></div><br>\nI think it would be better to enclose each of these function calls in their own try-except blocks. This screenshot is taken from the datagen.py file sent in yesterday\u2019s results mail.</p>\n<p>So, will it be possible to re-evaluate my task A1, A8, A9 and A10? At least A9 and A10 did not even get the files to work on as they weren\u2019t even created due to insufficient error handling in datagen.py .</p>\n<p>Also, can you help me to identify the cause of even the Pillow default font not being available? I don\u2019t understand how a font not being available could be caused by my code.</p>\n<p>Thank you</p>", "post_number": 114, "post_type": 1, "posts_count": 467, "updated_at": "2025-03-29T13:24:44.800Z", "reply_count": 1, "reply_to_post_number": null, "quote_count": 0, "incoming_link_count": 8, "reads": 100, "readers_count": 99, "score": 64.6, "yours": false, "topic_id": 171141, "topic_slug": "tds-official-project1-discrepencies", "display_username": "Shivaditya Bhattacharya", "primary_group_name": "ds-students", "flair_name": "ds-students", "flair_url": null, "flair_bg_color": "", "flair_color": "", "flair_group_id": 294, "badges_granted": [], "version": 1, "can_edit": false, "can_delete": false, "can_recover": false, "can_see_hidden_post": false, "can_wiki": false, "read": false, "user_title": "", "bookmarked": false, "actions_summary": [{"id": 2, "can_act": true}, {"id": 6, "can_act": true}, {"id": 3, "can_act": true}, {"id": 4, "can_act": true}, {"id": 8, "can_act": true}, {"id": 10, "can_act": true}, {"id": 7, "can_act": true}], "moderator": false, "admin": false, "staff": false, "user_id": 16002, "hidden": false, "trust_level": 1, "deleted_at": null, "user_deleted": false, "edit_reason": null, "can_view_edit_history": true, "wiki": false, "post_url": "/t/tds-official-project1-discrepencies/171141/114", "user_cakedate": "2023-01-25", "user_birthdate": "1904-03-07", "reactions": [], "current_user_reaction": null, "reaction_users_count": 0, "current_user_used_main_reaction": false, "can_accept_answer": false, "can_unaccept_answer": false, "accepted_answer": false, "topic_accepted_answer": null}