---
post_url: /t/ga3-large-language-models-discussion-thread-tds-jan-2025/163247/87
---
For question 1 getting the below response … not sure what it means  
ythonError: Traceback (most recent call last): File “/lib/python312.zip/\_pyodide/\_base.py”, line 523, in eval\_code .run(globals, locals) ^^^^^^^^^^^^^^^^^^^^ File “/lib/python312.zip/\_pyodide/\_base.py”, line 357, in run coroutine = eval(self.code, globals, locals) ^^^^^^^^^^^^^^^^^^^^^^^^^^^^^^^^ File “”, line 53, in TypeError: unhashable type: ‘dict’