{"id": 587764, "name": "Andrew David", "username": "23f1002382", "avatar_template": "/user_avatar/discourse.onlinedegree.iitm.ac.in/23f1002382/{size}/68945_2.png", "created_at": "2025-01-30T06:26:20.605Z", "cooked": "<p>I had set up the environment and dependencies and everything was working fine. When i tried to recreate it from scratch in a new codespace it broke. I fixed almost everything except this error</p>\n<pre><code class=\"lang-auto\">@ANdIeCOOl \u279c /workspaces/TDS-Project-1 (main) $ crewai create crew b2b\nTraceback (most recent call last):\n  File \"/home/codespace/.python/current/bin/crewai\", line 5, in &lt;module&gt;\n    from crewai.cli.cli import crewai\n  File \"/usr/local/python/3.12.1/lib/python3.12/site-packages/crewai/__init__.py\", line 3, in &lt;module&gt;\n    from crewai.agent import Agent\n  File \"/usr/local/python/3.12.1/lib/python3.12/site-packages/crewai/agent.py\", line 7, in &lt;module&gt;\n    from crewai.agents import CacheHandler\n  File \"/usr/local/python/3.12.1/lib/python3.12/site-packages/crewai/agents/__init__.py\", line 2, in &lt;module&gt;\n    from .parser import CrewAgentParser\n  File \"/usr/local/python/3.12.1/lib/python3.12/site-packages/crewai/agents/parser.py\", line 6, in &lt;module&gt;\n    from crewai.utilities import I18N\n  File \"/usr/local/python/3.12.1/lib/python3.12/site-packages/crewai/utilities/__init__.py\", line 13, in &lt;module&gt;\n    from .embedding_configurator import EmbeddingConfigurator\n  File \"/usr/local/python/3.12.1/lib/python3.12/site-packages/crewai/utilities/embedding_configurator.py\", line 4, in &lt;module&gt;\n    from chromadb import Documents, EmbeddingFunction, Embeddings\n  File \"/usr/local/python/3.12.1/lib/python3.12/site-packages/chromadb/__init__.py\", line 6, in &lt;module&gt;\n    from chromadb.auth.token_authn import TokenTransportHeader\n  File \"/usr/local/python/3.12.1/lib/python3.12/site-packages/chromadb/auth/token_authn/__init__.py\", line 24, in &lt;module&gt;\n    from chromadb.telemetry.opentelemetry import (\n  File \"/usr/local/python/3.12.1/lib/python3.12/site-packages/chromadb/telemetry/opentelemetry/__init__.py\", line 13, in &lt;module&gt;\n    from opentelemetry.exporter.otlp.proto.grpc.trace_exporter import OTLPSpanExporter\n  File \"/usr/local/python/3.12.1/lib/python3.12/site-packages/opentelemetry/exporter/otlp/proto/grpc/trace_exporter/__init__.py\", line 25, in &lt;module&gt;\n    from opentelemetry.exporter.otlp.proto.grpc.exporter import (  # noqa: F401\n  File \"/usr/local/python/3.12.1/lib/python3.12/site-packages/opentelemetry/exporter/otlp/proto/grpc/exporter.py\", line 72, in &lt;module&gt;\n    from opentelemetry.sdk.metrics.export import MetricsData\n  File \"/usr/local/python/3.12.1/lib/python3.12/site-packages/opentelemetry/sdk/metrics/__init__.py\", line 16, in &lt;module&gt;\n    from opentelemetry.sdk.metrics._internal import Meter, MeterProvider\n  File \"/usr/local/python/3.12.1/lib/python3.12/site-packages/opentelemetry/sdk/metrics/_internal/__init__.py\", line 56, in &lt;module&gt;\n    from opentelemetry.sdk.metrics._internal.measurement_consumer import (\n  File \"/usr/local/python/3.12.1/lib/python3.12/site-packages/opentelemetry/sdk/metrics/_internal/measurement_consumer.py\", line 29, in &lt;module&gt;\n    from opentelemetry.sdk.metrics._internal.metric_reader_storage import (\n  File \"/usr/local/python/3.12.1/lib/python3.12/site-packages/opentelemetry/sdk/metrics/_internal/metric_reader_storage.py\", line 26, in &lt;module&gt;\n    from opentelemetry.sdk.metrics._internal._view_instrument_match import (\n  File \"/usr/local/python/3.12.1/lib/python3.12/site-packages/opentelemetry/sdk/metrics/_internal/_view_instrument_match.py\", line 22, in &lt;module&gt;\n    from opentelemetry.sdk.metrics._internal.aggregation import (\n  File \"/usr/local/python/3.12.1/lib/python3.12/site-packages/opentelemetry/sdk/metrics/_internal/aggregation.py\", line 48, in &lt;module&gt;\n    from opentelemetry.sdk.metrics._internal.exponential_histogram.mapping.exponent_mapping import (\n  File \"/usr/local/python/3.12.1/lib/python3.12/site-packages/opentelemetry/sdk/metrics/_internal/exponential_histogram/mapping/exponent_mapping.py\", line 25, in &lt;module&gt;\n    from opentelemetry.sdk.metrics._internal.exponential_histogram.mapping.ieee_754 import (\n  File \"/usr/local/python/3.12.1/lib/python3.12/site-packages/opentelemetry/sdk/metrics/_internal/exponential_histogram/mapping/ieee_754.py\", line 15, in &lt;module&gt;\n    from ctypes import c_double, c_uint64\n  File \"/usr/local/python/3.12.1/lib/python3.12/ctypes/__init__.py\", line 8, in &lt;module&gt;\n    from _ctypes import Union, Structure, Array\nImportError: /usr/local/python/3.12.1/lib/python3.12/lib-dynload/_ctypes.cpython-312-x86_64-linux-gnu.so: undefined symbol: ffi_type_uint32, version LIBFFI_BASE_7.0\n</code></pre>\n<p>i updated the libffi package using sudo but while breaking something else can someone pls help me? <a class=\"mention\" href=\"/u/carlton\">@carlton</a> <a class=\"mention\" href=\"/u/jivraj\">@Jivraj</a> <a class=\"mention\" href=\"/u/s.anand\">@s.anand</a><br>\n<br><br>\n<br><br>\n<br></p>\n<p>history of commands in new codespace</p>\n<pre><code class=\"lang-auto\">    1  crewai --version\n    2  pip install crewai crewai-tools\n    3  python3 -c \"import sqlite3; print(sqlite3.sqlite_version)\"\n    4  export PATH=/opt/conda/bin:$PATH\n    5  export LD_LIBRARY_PATH=/opt/conda/lib:$LD_LIBRARY_PATH\n    6  python3 -c \"import sqlite3; print(sqlite3.sqlite_version)\"\n    7  crewai create crew &lt;project_name&gt;\n    8  crewai create crew b2b\n    9  history\n</code></pre>\n<br>\n<br>\n<p>UPDATE: IT\u2019s WORKING if you do this in order</p>\n<pre><code class=\"lang-auto\">    1  python3 -c \"import sqlite3; print(sqlite3.sqlite_version)\"\n    2  export PATH=/opt/conda/bin:$PATH\n    3  export LD_LIBRARY_PATH=/opt/conda/lib:$LD_LIBRARY_PATH\n    4  python3 -c \"import sqlite3; print(sqlite3.sqlite_version)\"\n    5  pip install --no-cache-dir --force-reinstall typing_extensions pydantic crewai crewai-tools\n    6  conda install -c conda-forge typing_extensions\n    7  exec bash\n    8  crewai create crew \"Project 1 - LLM-based Automation Agent\"\n</code></pre>\n<p>Something about different environment conda and python can the instructors please help me understand it(resources ), so i can trouble shoot this later with better accuracy come precision</p>", "post_number": 35, "post_type": 1, "posts_count": 614, "updated_at": "2025-01-30T07:05:09.963Z", "reply_count": 0, "reply_to_post_number": null, "quote_count": 0, "incoming_link_count": 8, "reads": 364, "readers_count": 363, "score": 127.4, "yours": false, "topic_id": 164277, "topic_slug": "project-1-llm-based-automation-agent-discussion-thread-tds-jan-2025", "display_username": "Andrew David", "primary_group_name": "ds-students", "flair_name": "ds-students", "flair_url": null, "flair_bg_color": "", "flair_color": "", "flair_group_id": 294, "badges_granted": [], "version": 3, "can_edit": false, "can_delete": false, "can_recover": false, "can_see_hidden_post": false, "can_wiki": false, "read": true, "user_title": null, "bookmarked": false, "actions_summary": [{"id": 2, "count": 1, "can_act": true}, {"id": 6, "can_act": true}, {"id": 3, "can_act": true}, {"id": 4, "can_act": true}, {"id": 8, "can_act": true}, {"id": 10, "can_act": true}, {"id": 7, "can_act": true}], "moderator": false, "admin": false, "staff": false, "user_id": 18297, "hidden": false, "trust_level": 1, "deleted_at": null, "user_deleted": false, "edit_reason": null, "can_view_edit_history": true, "wiki": false, "post_url": "/t/project-1-llm-based-automation-agent-discussion-thread-tds-jan-2025/164277/35", "user_cakedate": "2023-06-05", "user_birthdate": "1904-01-05", "reactions": [{"id": "heart", "type": "emoji", "count": 1}], "current_user_reaction": null, "reaction_users_count": 1, "current_user_used_main_reaction": false, "can_accept_answer": false, "can_unaccept_answer": false, "accepted_answer": false, "topic_accepted_answer": null}